2024-08-12 10:23:13,496 INFO: App startup [in /home/star/project/AiFriend/app/__init__.py:51]
2024-08-12 11:10:31,407 INFO: App startup [in /home/star/project/AiFriend/app/__init__.py:51]
2024-08-12 11:10:31,524 INFO: App startup [in /home/star/project/AiFriend/app/__init__.py:51]
2024-08-12 11:11:22,170 ERROR: Failed to save AI test result: (pymysql.err.OperationalError) (1698, "Access denied for user 'root'@'localhost'")
(Background on this error at: https://sqlalche.me/e/20/e3q8) [in /home/star/project/AiFriend/app/ai_chat.py:76]
2024-08-12 11:11:22,170 ERROR: Failed to save the test result to the database, but proceeding to send the response. [in /home/star/project/AiFriend/app/ai_chat.py:132]
2024-08-12 11:12:33,039 ERROR: Failed to parse AI response: Expecting ',' delimiter: line 6 column 34 (char 94) [in /home/star/project/AiFriend/app/ai_chat.py:113]
2024-08-12 11:12:33,039 ERROR: Error: An error occurred while parsing the AI response. [in /home/star/project/AiFriend/app/ai_chat.py:192]
2024-08-12 11:12:55,573 INFO: App startup [in /home/star/project/AiFriend/app/__init__.py:51]
2024-08-12 11:14:54,914 INFO: App startup [in /home/star/project/AiFriend/app/__init__.py:51]
2024-08-12 11:14:55,018 INFO: App startup [in /home/star/project/AiFriend/app/__init__.py:51]
2024-08-12 11:41:20,922 INFO: App startup [in /home/star/project/AiFriend/app/__init__.py:51]
2024-08-12 12:48:56,535 INFO: App startup [in /home/star/project/AiFriend/app/__init__.py:51]
2024-08-12 12:48:56,663 INFO: App startup [in /home/star/project/AiFriend/app/__init__.py:51]
2024-08-13 10:49:33,341 INFO: App startup [in C:\project\sesac\aiFriend\app\__init__.py:51]
2024-08-13 10:51:57,680 INFO: App startup [in C:\project\sesac\aiFriend\app\__init__.py:51]
2024-08-13 11:13:07,537 INFO: App startup [in C:\project\sesac\aiFriend\app\__init__.py:51]
2024-08-13 11:55:11,343 INFO: App startup [in C:\project\sesac\aiFriend\app\__init__.py:51]
2024-08-13 12:00:05,852 INFO: App startup [in C:\project\sesac\aiFriend\app\__init__.py:51]
2024-08-13 13:29:20,420 INFO: App startup [in C:\project\sesac\aiFriend\app\__init__.py:51]
2024-08-13 13:40:02,479 INFO: App startup [in C:\project\sesac\aiFriend\app\__init__.py:51]
2024-08-13 13:43:53,708 INFO: App startup [in C:\project\sesac\aiFriend\app\__init__.py:51]
2024-08-13 13:48:24,498 ERROR: Failed to save AI test result: (pymysql.err.IntegrityError) (1452, 'Cannot add or update a child row: a foreign key constraint fails (`aifriend`.`ai_chat_test`, CONSTRAINT `ai_chat_test_ibfk_1` FOREIGN KEY (`topic_id`) REFERENCES `topic` (`topic_id`))')
[SQL: INSERT INTO ai_chat_test (`chatTest_id`, user_id, `chatDate`, topic_id, fluency, grammar, vocabulary, content, `simpleEvaluation`) VALUES (%(chatTest_id)s, %(user_id)s, %(chatDate)s, %(topic_id)s, %(fluency)s, %(grammar)s, %(vocabulary)s, %(content)s, %(simpleEvaluation)s)]
[parameters: {'chatTest_id': '8f0ec069-0e55-4f43-bf71-865bf484942b', 'user_id': 'abc1234', 'chatDate': datetime.datetime(2024, 8, 13, 4, 48, 24, 463453), 'topic_id': '1', 'fluency': 5, 'grammar': 4, 'vocabulary': 3, 'content': 6, 'simpleEvaluation': "You're doing great."}]
(Background on this error at: https://sqlalche.me/e/20/gkpj) [in C:\project\sesac\aiFriend\app\ai_chat.py:81]
2024-08-13 13:48:24,499 ERROR: Failed to save the test result to the database, but proceeding to send the response. [in C:\project\sesac\aiFriend\app\ai_chat.py:137]
2024-08-13 13:49:09,713 INFO: App startup [in C:\project\sesac\aiFriend\app\__init__.py:51]
2024-08-13 13:50:18,146 ERROR: Failed to save AI test result: (pymysql.err.IntegrityError) (1452, 'Cannot add or update a child row: a foreign key constraint fails (`aifriend`.`ai_chat_test`, CONSTRAINT `ai_chat_test_ibfk_1` FOREIGN KEY (`topic_id`) REFERENCES `topic` (`topic_id`))')
[SQL: INSERT INTO ai_chat_test (`chatTest_id`, user_id, `chatDate`, topic_id, fluency, grammar, vocabulary, content, `simpleEvaluation`) VALUES (%(chatTest_id)s, %(user_id)s, %(chatDate)s, %(topic_id)s, %(fluency)s, %(grammar)s, %(vocabulary)s, %(content)s, %(simpleEvaluation)s)]
[parameters: {'chatTest_id': 'ac010192-d4cd-44f0-9d30-bacc913088eb', 'user_id': 'abc1234', 'chatDate': datetime.datetime(2024, 8, 13, 4, 50, 18, 112353), 'topic_id': '1', 'fluency': 4, 'grammar': 5, 'vocabulary': 3, 'content': 6, 'simpleEvaluation': "You're doing great."}]
(Background on this error at: https://sqlalche.me/e/20/gkpj) [in C:\project\sesac\aiFriend\app\ai_chat.py:81]
2024-08-13 13:50:18,150 ERROR: Failed to save the test result to the database, but proceeding to send the response. [in C:\project\sesac\aiFriend\app\ai_chat.py:137]
2024-08-13 13:54:27,074 INFO: App startup [in C:\project\sesac\aiFriend\app\__init__.py:51]
2024-08-13 13:56:06,798 ERROR: Failed to save AI test result: (pymysql.err.IntegrityError) (1452, 'Cannot add or update a child row: a foreign key constraint fails (`aifriend`.`ai_chat_test`, CONSTRAINT `ai_chat_test_ibfk_1` FOREIGN KEY (`topic_id`) REFERENCES `topic` (`topic_id`))')
[SQL: INSERT INTO ai_chat_test (`chatTest_id`, user_id, `chatDate`, topic_id, fluency, grammar, vocabulary, content, `simpleEvaluation`) VALUES (%(chatTest_id)s, %(user_id)s, %(chatDate)s, %(topic_id)s, %(fluency)s, %(grammar)s, %(vocabulary)s, %(content)s, %(simpleEvaluation)s)]
[parameters: {'chatTest_id': 'b9619008-d7eb-4675-8108-65bdeab0cc51', 'user_id': 'abc1234', 'chatDate': datetime.datetime(2024, 8, 13, 4, 56, 6, 775159), 'topic_id': '1', 'fluency': 5, 'grammar': 4, 'vocabulary': 6, 'content': 7, 'simpleEvaluation': "You're doing great."}]
(Background on this error at: https://sqlalche.me/e/20/gkpj) [in C:\project\sesac\aiFriend\app\ai_chat.py:81]
2024-08-13 13:56:06,801 ERROR: Failed to save the test result to the database, but proceeding to send the response. [in C:\project\sesac\aiFriend\app\ai_chat.py:137]
2024-08-13 13:57:56,442 ERROR: Failed to save AI test result: (pymysql.err.IntegrityError) (1452, 'Cannot add or update a child row: a foreign key constraint fails (`aifriend`.`ai_chat_test`, CONSTRAINT `ai_chat_test_ibfk_1` FOREIGN KEY (`topic_id`) REFERENCES `topic` (`topic_id`))')
[SQL: INSERT INTO ai_chat_test (`chatTest_id`, user_id, `chatDate`, topic_id, fluency, grammar, vocabulary, content, `simpleEvaluation`) VALUES (%(chatTest_id)s, %(user_id)s, %(chatDate)s, %(topic_id)s, %(fluency)s, %(grammar)s, %(vocabulary)s, %(content)s, %(simpleEvaluation)s)]
[parameters: {'chatTest_id': '7c591868-be2c-441c-8a2f-27b647f63d52', 'user_id': 'abc1234', 'chatDate': datetime.datetime(2024, 8, 13, 4, 57, 56, 432014), 'topic_id': '1', 'fluency': 6, 'grammar': 7, 'vocabulary': 5, 'content': 8, 'simpleEvaluation': "You're doing great."}]
(Background on this error at: https://sqlalche.me/e/20/gkpj) [in C:\project\sesac\aiFriend\app\ai_chat.py:81]
2024-08-13 13:57:56,445 ERROR: Failed to save the test result to the database, but proceeding to send the response. [in C:\project\sesac\aiFriend\app\ai_chat.py:137]
